Workbook

Sheet 성장그래프
A1: 기간 | B1: 판매금액 | C1: 전분기 대비 성장률(QoQ) | D1: 전년 동기 대비 성장률(YoY)
A2: 이전 | B2: 155980124
A3: 2018년 2분기 | B3: 257161331
A4: 2018년 3분기 | B4: 345233092 | C4: =(B4-B3)/B3 -> 0.34247669
A5: 2018년 4분기 | B5: 416236156 | C5: =(B5-B4)/B4 -> 0.20566703
A6: 2019년 1분기 | B6: 433143497 | C6: =(B6-B5)/B5 -> 0.040619588
A7: 2019년 2분기 | B7: 561338949 | C7: =(B7-B6)/B6 -> 0.29596532 | D7: =(B7-B3)/B3 -> 1.182828
A8: 2019년 3분기 | B8: 585347931 | C8: =(B8-B7)/B7 -> 0.042770918 | D8: =(B8-B4)/B4 -> 0.69551513
A9: 2019년 4분기 | B9: 622597864 | C9: =(B9-B8)/B8 -> 0.063637251 | D9: =(B9-B5)/B5 -> 0.49578035
A10: 2020년 1분기 | B10: 694752201 | C10: =(B10-B9)/B9 -> 0.11589236 | D10: =(B10-B6)/B6 -> 0.60397699
A11: 2020년 2분기 | B11: 982425838 | C11: =(B11-B10)/B10 -> 0.41406654 | D11: =(B11-B7)/B7 -> 0.75014729
A12: 2020년 3분기 | B12: 1074839252 | C12: =(B12-B11)/B11 -> 0.094066555 | D12: =(B12-B8)/B8 -> 0.83623994
A13: 2020년 4분기 | B13: 984813809 | C13: =(B13-B12)/B12 -> -0.083757123 | D13: =(B13-B9)/B9 -> 0.58178154
A14: 2021년 1분기 | B14: 806050477 | C14: =(B14-B13)/B13 -> -0.18151993 | D14: =(B14-B10)/B10 -> 0.16019852
A15: 2021년 2분기 | B15: 886675402 | C15: =(B15-B14)/B14 -> 0.10002466 | D15: =(B15-B11)/B11 -> -0.097463271
A16: 2021년 3분기 | B16: 925792941 | C16: =(B16-B15)/B15 -> 0.044117091 | D16: =(B16-B12)/B12 -> -0.13866847
A17: 2021년 4분기 | B17: 932938959 | C17: =(B17-B16)/B16 -> 0.007718808 | D17: =(B17-B13)/B13 -> -0.052674779
A18: 2022년 1분기 | B18: 904837364 | C18: =(B18-B17)/B17 -> -0.030121579 | D18: =(B18-B14)/B14 -> 0.1225567
... A34: 2026년 1분기 | B34: 1008519311 | C34: =(B34-B33)/B33 -> -0.11649808 | D34: =(B34-B30)/B30 -> -0.11970724
A35: 합계 | B35: =SUM(B2:B32) -> 25586840091

Sheet 성장그래프 (카카오페이 비중)
A1: 기간 | B1: 매출액 | C1: 카카오페이 | D1: 카카오페이 비중
A2: 2018년 2분기 | B2: 257161331
A3: 2018년 3분기 | B3: 345233092
A4: 2018년 4분기 | B4: 416236156
A5: 2019년 1분기 | B5: 433143497
A6: 2019년 2분기 | B6: 561338949 | C6: ='2019.04~06'!C16 -> 44101195 | D6: =C6/B6 -> 0.078564288
A7: 2019년 3분기 | B7: 585347931 | C7: ='2019.07~09'!C16 -> 54828476 | D7: =C7/B7 -> 0.093668181
A8: 2019년 4분기 | B8: 622597864 | C8: ='2019.10~12'!C16 -> 64676827 | D8: =C8/B8 -> 0.10388219
A9: 2020년 1분기 | B9: 694752201 | C9: ='2020.01~03'!C16 -> 76415333 | D9: =C9/B9 -> 0.10998934
A10: 2020년 2분기 | B10: 982425838 | C10: ='2020.04~06'!C16 -> 108875643 | D10: =C10/B10 -> 0.11082327
A11: 2020년 3분기 | B11: 1074839252 | C11: ='2020.07~09'!C16 -> 136731702 | D11: =C11/B11 -> 0.1272113
A12: 2020년 4분기 | B12: 984813809 | C12: ='2020.10~12'!C16 -> 154275616 | D12: =C12/B12 -> 0.1566546
A13: 2021년 1분기 | B13: 806050477 | C13: ='2021.01~03'!C16 -> 127796501 | D13: =C13/B13 -> 0.15854652
A14: 2021년 2분기 | B14: 886675402 | C14: ='2021.04~06'!C16 -> 152836797 | D14: =C14/B14 -> 0.17237063
A15: 2021년 3분기 | B15: 925792941 | C15: ='2021.07~09'!D16 -> 199323644 | D15: =C15/B15 -> 0.21530046
A16: 2021년 4분기 | B16: 932938959 | C16: ='2021.10~12'!D20 -> 207985258 | D16: =C16/B16 -> 0.22293555
A17: 2022년 1분기 | B17: 904837364 | C17: 173518976 | D17: =C17/B17 -> 0.19176814
A18: 2022년 2분기 | B18: 920727905 | C18: 167644933 | D18: =C18/B18 -> 0.18207869

Sheet 2018.04~06
B1: 2018년 4 ~ 6월 부가세 신고 정리
C2: 구분 | D2: 금액 | E2: 적요
B3: 홈페이지 | C3: 카드결제 | D3: 111037466 | E3: 신용카드 매출
C4: 무통장입금 | D4: 24353030 | E4: 무통장입금
C5: 계좌이체 | D5: 1000827 | E5: 실시간 계좌이체
C6: 가상계좌 | D6: 1406263
C7: 기타매출 | D7: 9667865 | E7: 핸드폰결제
C8: 합계 | D8: =SUM(D3:D7) -> 147465451
B9: 네이버페이 | C9: 신용카드 | D9: 82608572 | E9: 신용카드 매출
C10: 현금영수증(소득공제) | D10: 16601088
C11: 현금영수증(지출증빙) | D11: 1644084
C12: 기타 | D12: 8842136 | E12: 네이버포인트, 현금영수증 미발행 건 등
C13: 합계 | D13: =SUM(D9:D12) -> 109695880
B14: 매출 총합 | D14: =D8+D13 -> 257161331
B15: 홈택스 현금영수증 | C15: 4월 | D15: 4598672
C16: 5월 | D16: 9685830
C17: 6월 | D17: 8254682
C18: 합계 | D18: =SUM(D15:D17) -> 22539184 | E18: 홈페이지, 네이버페이 현금영수증 발행 총합

Sheet 2018.07~09
B1: 2018년 7 ~ 9월 부가세 신고 정리
C2: 구분 | D2: 금액 | E2: 적요
B3: 홈페이지 | C3: 카드결제 | D3: 130276433 | E3: 신용카드 매출
C4: 무통장입금 | D4: 28327686 | E4: 무통장입금
C5: 계좌이체 | D5: 1024165 | E5: 실시간 계좌이체
C6: 가상계좌 | D6: 1916551
C7: 기타매출 | D7: 11963957 | E7: 핸드폰결제
C8: 합계 | D8: =SUM(D3:D7) -> 173508792
B9: 네이버페이 | C9: 신용카드 | D9: 126292947 | E9: 신용카드 매출
C10: 현금영수증(소득공제) | D10: 28384583
C11: 현금영수증(지출증빙) | D11: 2313246
C12: 기타 | D12: 14733524 | E12: 네이버포인트, 현금영수증 미발행 건 등
C13: 합계 | D13: =SUM(D9:D12) -> 171724300
B14: 매출 총합 | D14: =D8+D13 -> 345233092
B15: 홈택스 현금영수증 | C15: 7월 | D15: 10527208
C16: 8월 | D16: 15042596
C17: 9월 | D17: 10793416
C18: 합계 | D18: =SUM(D15:D17) -> 36363220 | E18: 홈페이지, 네이버페이 현금영수증 발행 총합

Sheet 2018.10~12
B1: 2018년 10 ~ 12월 부가세 신고 정리
C2: 구분 | D2: 금액 | E2: 적요
B3: 홈페이지 | C3: 신용카드 | D3: 187876932 | E3: 신용카드 매출
C4: 무통장입금 | D4: 38811344 | E4: 무통장입금 건 - 취소환불 건
C5: 계좌이체 | D5: 1714378 | E5: 실시간 계좌이체
C6: 가상계좌 | D6: 2213597
C7: 기타매출 | D7: 15054445 | E7: 핸드폰결제
C8: 합계 | D8: =SUM(D3:D7) -> 245670696
B9: 네이버페이 | C9: 신용카드 | D9: 126772538 | E9: 신용카드 매출
C10: 현금영수증(소득공제) | D10: 27821612
C11: 현금영수증(지출증빙) | D11: 2498928
C12: 기타 | D12: 13472382 | E12: 네이버포인트, 현금영수증 미발행 건 등
C13: 합계 | D13: =SUM(D9:D12) -> 170565460
B14: 매출 총합 | D14: =D8+D13 -> 416236156
B15: 홈택스 현금영수증 | C15: 10월 | D15: 10758851
C16: 11월 | D16: 13513562
C17: 12월 | D17: 12053279
C18: 합계 | D18: =SUM(D15:D17) -> 36325692 | E18: 홈페이지, 네이버페이 현금영수증 발행 총합

Sheet 2019.01~03
B1: 2019년 1 ~ 3월 부가세 신고 정리
C2: 구분 | D2: 금액 | E2: 참고
B3: 홈페이지 | C3: 카드결제 | D3: 164821692 | E3: 신용카드 매출
C4: 무통장입금 | D4: 38009915 | E4: 무통장입금(이 중 일부 요청건 현금영수증 발행됨)
C5: 계좌이체 | D5: 1493073 | E5: 실시간 계좌이체(이 중 일부 요청건 현금영주승 발행됨)
C6: 가상계좌 | D6: 2201665 | E6: 이 중 일부 요청건 현금영수증 발행됨
C7: 기타매출 | D7: 12702008 | E7: 핸드폰결제
C8: 합계 | D8: =SUM(D3:D7) -> 219228353
B9: 네이버페이 | C9: 카드결제 | D9: 159755719 | E9: 신용카드 매출
C10: 현금영수증(소득공제) | D10: 35418993
C11: 현금영수증(지출증빙) | D11: 3538681
C12: 기타 | D12: 15201751 | E12: 네이버포인트, 현금영수증 미발행 건 등
C13: 합계 | D13: =SUM(D9:D12) -> 213915144
B14: 매출 총합 | D14: =D8+D13 -> 433143497
B15: 홈택스 현금영수증 | C15: 1월 | D15: 13374917
C16: 2월 | D16: 12324838
C17: 3월 | D17: 19512422
C18: 합계 | D18: =SUM(D15:D17) -> 45212177 | E18: 홈페이지, 네이버페이 현금영수증 발행 총합

Sheet 2019.04~06
A1: 2019년 4 ~ 6월 부가세 신고 정리
B2: 구분 | C2: 금액 | D2: 참고
A3: 홈페이지 (나이스페이 & 무통장입금) | B3: 카드결제 | C3: 221397485 | D3: 신용카드 매출
B4: 무통장입금 | C4: 38641969 | D4: 무통장입금(이 중 일부 요청건 현금영수증 발행됨)
B5: 계좌이체 | C5: 1240690 | D5: 실시간 계좌이체(이 중 일부 요청건 현금영주승 발행됨)
B6: 가상계좌 | C6: 1945120 | D6: 이 중 일부 요청건 현금영수증 발행됨
B7: 기타매출 | C7: 17126704 | D7: 핸드폰결제
B8: 합계 | C8: =SUM(C3:C7) -> 280351968
A9: 네이버페이 | B9: 카드결제 | C9: 163862203 | D9: 신용카드 매출
B10: 현금영수증(소득공제) | C10: 50916863
B11: 현금영수증(지출증빙) | C11: 3703467
B12: 기타 | C12: 18403253 | D12: 네이버포인트, 현금영수증 미발행 건 등
B13: 합계 | C13: =SUM(C9:C12) -> 236885786
A14: 홈페이지 (카카오페이) | B14: 카드결제 | C14: 17243356 | D14: 신용카드 매출
B15: 현금 | C15: 26857839 | D15: 카카오페이 사용 시 등록번호로 현금영수증 자동발행
B16: 합계 | C16: =SUM(C14:C15) -> 44101195
A17: 매출 총합 | C17: =C8+C13+C16 -> 561338949
A18: 홈택스 현금영수증 | B18: 4월 | C18: 28317377
B19: 5월 | C19: 27466781
B20: 6월 | C20: 32413044
B21: 합계 | C21: =SUM(C18:C20) -> 88197202 | D21: 홈페이지, 나이스/네이버/카카오페이 현금영수증 발행 총합

Sheet 2019.07~09
A1: 2019년 7 ~ 9월 매출금액 결제수단 별 정리
B2: 구분 | C2: 금액 | D2: 참고
A3: 홈페이지 (나이스페이 & 무통장입금) | B3: 카드결제 | C3: 231397683
B4: 무통장입금 | C4: 38570811 | D4: 무통장입금(이 중 일부 요청건 현금영수증 발행됨)
B5: 계좌이체 | C5: 912282 | D5: 실시간 계좌이체(이 중 일부 요청건 현금영주승 발행됨)
B6: 가상계좌 | C6: 1507497 | D6: 이 중 일부 요청건 현금영수증 발행됨
B7: 기타매출 | C7: 17090961 | D7: 핸드폰결제
B8: 합계 | C8: =SUM(C3:C7) -> 289479234
A9: 네이버페이 | B9: 카드결제 | C9: 166447348 | D9: 신용카드 매출
B10: 현금영수증(소득공제) | C10: 53613926
B11: 현금영수증(지출증빙) | C11: 3023384
B12: 기타 | C12: 17955563 | D12: 네이버포인트, 현금영수증 미발행 건 등
B13: 합계 | C13: =SUM(C9:C12) -> 241040221
A14: 홈페이지 (카카오페이) | B14: 카드결제 | C14: 21435585 | D14: 신용카드 매출
B15: 현금 | C15: 33392891 | D15: 카카오페이 사용 시 등록번호로 현금영수증 자동발행
B16: 합계 | C16: =SUM(C14:C15) -> 54828476
A17: 매출 총합 | C17: =C8+C13+C16 -> 585347931
A18: 홈택스 현금영수증 | B18: 7월 | C18: 34841991
B19: 8월 | C19: 35550636
B20: 9월 | C20: 28170929
B21: 합계 | C21: =SUM(C18:C20) -> 98563556 | D21: 홈페이지, 나이스/네이버/카카오페이 현금영수증 발행 총합

Sheet 2019.10~12
A1: 2019년 10 ~ 12월 매출금액 결제수단 별 정리
B2: 구분 | C2: 금액 | D2: 참고
A3: 홈페이지 (나이스페이 & 무통장입금) | B3: 카드결제 | C3: 281047882
B4: 무통장입금 | C4: 53265073 | D4: 무통장입금(이 중 일부 요청건 현금영수증 발행됨)
B5: 계좌이체 | C5: 595628 | D5: 실시간 계좌이체(이 중 일부 요청건 현금영주승 발행됨)
B6: 가상계좌 | C6: 1841086 | D6: 이 중 일부 요청건 현금영수증 발행됨
B7: 기타매출 | C7: 19941119 | D7: 핸드폰결제
B8: 합계 | C8: =SUM(C3:C7) -> 356690788
A9: 네이버페이 | B9: 카드결제 | C9: 134937876 | D9: 신용카드 매출
B10: 현금영수증(소득공제) | C10: 49366375
B11: 현금영수증(지출증빙) | C11: 2979504
B12: 기타 | C12: 13946494 | D12: 네이버포인트, 현금영수증 미발행 건 등
B13: 합계 | C13: =SUM(C9:C12) -> 201230249
A14: 홈페이지 (카카오페이) | B14: 카드결제 | C14: 25190169 | D14: 신용카드 매출
B15: 현금 | C15: 39486658 | D15: 카카오페이 사용 시 등록번호로 현금영수증 자동발행
B16: 합계 | C16: =SUM(C14:C15) -> 64676827
A17: 매출 총합 | C17: =C8+C13+C16 -> 622597864
A18: 홈택스 현금영수증 | B18: 10월 | C18: 34657604
B19: 11월 | C19: 31090706
B20: 12월 | C20: 33208154
B21: 합계 | C21: =SUM(C18:C20) -> 98956464 | D21: 무통장입금, 나이스/네이버/카카오페이 현금영수증 발행 총합

Sheet 2020.01~03
A1: 2020년 01 ~ 03월 매출금액 결제수단 별 정리
B2: 구분 | C2: 금액 | D2: 참고
A3: 홈페이지 (나이스페이 & 무통장입금) | B3: 카드결제 | C3: 330852535
B4: 무통장입금 | C4: 55337580 | D4: 무통장입금액-취소환불금액(56,634,554-1,296,974) / 일부 현금영수증 발행됨
B5: 계좌이체 | C5: 682894 | D5: 실시간 계좌이체(이 중 일부 현금영수증 발행됨)
B6: 가상계좌 | C6: 2367038 | D6: 이 중 일부 요청건 현금영수증 발행됨
B7: 기타매출 | C7: 19291829 | D7: 핸드폰결제
B8: 합계 | C8: =SUM(C3:C7) -> 408531876
A9: 네이버페이 | B9: 카드결제 | C9: 143215068 | D9: 신용카드 매출
B10: 현금영수증(소득공제) | C10: 50039148
B11: 현금영수증(지출증빙) | C11: 2936281
B12: 기타 | C12: 13614495 | D12: 네이버포인트, 현금영수증 미발행 건 등
B13: 합계 | C13: =SUM(C9:C12) -> 209804992
A14: 홈페이지 (카카오페이) | B14: 카드결제 | C14: 29428303 | D14: 신용카드 매출
B15: 현금 | C15: 46987030 | D15: 카카오페이 사용 시 등록번호로 현금영수증 자동발행
B16: 합계 | C16: =SUM(C14:C15) -> 76415333
A17: 매출 총합 | C17: =C8+C13+C16 -> 694752201
A18: 홈택스 현금영수증 | B18: 1월 | C18: 28753315
B19: 2월 | C19: 39871745
B20: 3월 | C20: 40121672
B21: 합계 | C21: =SUM(C18:C20) -> 108746732 | D21: 무통장입금, 나이스/네이버/카카오페이 현금영수증 발행 총합

Sheet 2020.04~06
A1: 2020년 04 ~ 06월 매출금액 결제수단 별 정리
B2: 구분 | C2: 금액 | D2: 참고
A3: 홈페이지 (나이스페이 & 무통장입금) | B3: 카드결제 | C3: 438953146
B4: 무통장입금 | C4: 78175495 | D4: 무통장입금액-취소환불금액(80,740,856-2,565,361) / 일부 현금영수증 발행됨
B5: 계좌이체 | C5: 983209 | D5: 실시간 계좌이체(이 중 일부 현금영수증 발행됨)
B6: 가상계좌 | C6: 3581069 | D6: 이 중 일부 요청건 현금영수증 발행됨
B7: 기타매출 | C7: 23682100 | D7: 핸드폰결제
B8: 합계 | C8: =SUM(C3:C7) -> 545375019
A9: 네이버페이 | B9: 카드결제 | C9: 217265799 | D9: 신용카드 매출
B10: 현금영수증(소득공제) | C10: 85772849
B11: 현금영수증(지출증빙) | C11: 4023138
B12: 기타 | C12: 21113390 | D12: 네이버포인트, 현금영수증 미발행 건 등
B13: 합계 | C13: =SUM(C9:C12) -> 328175176
A14: 홈페이지 (카카오페이) | B14: 카드결제 | C14: 39511733 | D14: 신용카드 매출
B15: 현금 | C15: 69363910 | D15: 카카오페이 사용 시 등록번호로 현금영수증 자동발행
B16: 합계 | C16: =SUM(C14:C15) -> 108875643
A17: 매출 총합 | C17: =C8+C13+C16 -> 982425838 | D17: =C17/1.1 -> 8.931144e+08
A18: 홈택스 현금영수증 | B18: 4월 | C18: 56299873
B19: 5월 | C19: 56664732
B20: 6월 | C20: 61664245
B21: 합계 | C21: =SUM(C18:C20) -> 174628850 | D21: 무통장입금, 나이스/네이버/카카오페이 현금영수증 발행 총합

Sheet 2020.07~09
A1: 2020년 07 ~ 09월 매출금액 결제수단 별 정리
B2: 구분 | C2: 금액 | D2: 참고
A3: 홈페이지 (나이스페이 & 무통장입금) | B3: 카드결제 | C3: 497386711
B4: 무통장입금 | C4: 94356370 | D4: 무통장입금액-취소환불금액(96,695,515-2,339,145) / 일부 현금영수증 발행됨
B5: 계좌이체 | C5: 1140236 | D5: 실시간 계좌이체(이 중 일부 현금영수증 발행됨)
B6: 가상계좌 | C6: 3100712 | D6: 이 중 일부 요청건 현금영수증 발행됨
B7: 기타매출 | C7: 28562529 | D7: 핸드폰결제
B8: 합계 | C8: =SUM(C3:C7) -> 624546558
A9: 네이버페이 | B9: 카드결제 | C9: 202083967 | D9: 신용카드 매출
B10: 현금영수증(소득공제) | C10: 85046470
B11: 현금영수증(지출증빙) | C11: 4937121
B12: 기타 | C12: 21493434 | D12: 네이버포인트, 현금영수증 미발행 건 등
B13: 합계 | C13: =SUM(C9:C12) -> 313560992
A14: 홈페이지 (카카오페이) | B14: 카드결제 | C14: 48776013 | D14: 신용카드 매출
B15: 현금 | C15: 87955689 | D15: 카카오페이 사용 시 등록번호로 현금영수증 자동발행
B16: 합계 | C16: =SUM(C14:C15) -> 136731702
A17: 매출 총합 | C17: =C8+C13+C16 -> 1074839252
A18: 홈택스 현금영수증 | B18: 7월 | C18: 66163399
B19: 8월 | C19: 59687627
B20: 9월 | C20: 66402038
B21: 합계 | C21: =SUM(C18:C20) -> 192253064 | D21: 무통장입금, 나이스/네이버/카카오페이 현금영수증 발행 총합

Sheet 2020.10~12
A1: 2020년 10 ~ 12월 매출금액 결제수단 별 정리
B2: 구분 | C2: 금액 | D2: 참고
A3: 홈페이지 (나이스페이 & 무통장입금) | B3: 카드결제 | C3: 508414925
B4: 무통장입금 | C4: 79686428 | D4: 무통장입금액-취소환불금액(81,970,487-2,284,059) / 일부 현금영수증 발행됨
B5: 계좌이체 | C5: 1549880 | D5: 실시간 계좌이체(이 중 일부 현금영수증 발행됨)
B6: 가상계좌 | C6: 2730943 | D6: 이 중 일부 요청건 현금영수증 발행됨
B7: 기타매출 | C7: 24928237 | D7: 핸드폰결제
B8: 합계 | C8: =SUM(C3:C7) -> 617310413
A9: 네이버페이 | B9: 카드결제 | C9: 131243010 | D9: 신용카드 매출
B10: 현금영수증(소득공제) | C10: 63475729
B11: 현금영수증(지출증빙) | C11: 3460955
B12: 기타 | C12: 15048086 | D12: 네이버포인트, 현금영수증 미발행 건 등
B13: 합계 | C13: =SUM(C9:C12) -> 213227780
A14: 홈페이지 (카카오페이) | B14: 카드결제 | C14: 55238223 | D14: 신용카드 매출
B15: 현금 | C15: 99037393 | D15: 카카오페이 사용 시 등록번호로 현금영수증 자동발행
B16: 합계 | C16: =SUM(C14:C15) -> 154275616
A17: 매출 총합 | C17: =C8+C13+C16 -> 984813809
A18: 홈택스 현금영수증 | B18: 10월 | C18: 61846382
B19: 11월 | C19: 54626501
B20: 12월 | C20: 61526957
B21: 합계 | C21: =SUM(C18:C20) -> 177999840 | D21: 무통장입금, 나이스/네이버/카카오페이 현금영수증 발행 총합

Sheet 2021.01~03
A1: 2021년 1 ~ 3월 매출금액 결제수단 별 정리
B2: 구분 | C2: 금액 | D2: 참고
A3: 홈페이지 (나이스페이 & 무통장입금) | B3: 카드결제 | C3: 383044446
B4: 무통장입금 | C4: 53394170 | D4: 무통장입금액-취소환불금액(54,595,600-1,201,430) / 일부 현금영수증 발행됨
B5: 계좌이체 | C5: 1021697 | D5: 실시간 계좌이체(이 중 일부 현금영수증 발행됨)
B6: 가상계좌 | C6: 1593191 | D6: 이 중 일부 요청건 현금영수증 발행됨
B7: 기타매출 | C7: 19943046 | D7: 핸드폰결제
B8: 합계 | C8: =SUM(C3:C7) -> 458996550
A9: 네이버페이 | B9: 카드결제 | C9: 123890594 | D9: 신용카드 매출
B10: 현금영수증(소득공제) | C10: 67391081
B11: 현금영수증(지출증빙) | C11: 3512995
B12: 기타 | C12: 15126906 | D12: 네이버포인트, 현금영수증 미발행 건 등
B13: 합계 | C13: =SUM(C9:C12) -> 209921576
A14: 홈페이지 (카카오페이) | B14: 카드결제 | C14: 47618794 | D14: 신용카드 매출
B15: 현금 | C15: 80177707 | D15: 카카오페이 사용 시 등록번호로 현금영수증 자동발행
B16: 합계 | C16: =SUM(C14:C15) -> 127796501
A17: 네이버 스마트스토어 | B17: 카드결제 | C17: 5065597
B18: 현금영수증(소득공제) | C18: 2536039
B19: 현금영수증(지출증빙) | C19: 46100
B20: 기타 | C20: 786734 | D20: 네이버포인트, 현금영수증 미발행 건 등
B21: 합계 | C21: =SUM(C17:C20) -> 8434470
A22: 매출 총합 | C22: =C8+C13+C16+C21 -> 805149097
A23: 홈택스 현금영수증 | B23: 1월 | C23: 3433416
B24: 2월 | C24: 1813262
B25: 3월 | C25: 2723752
B26: 합계 | C26: =SUM(C23:C25) -> 7970430 | D26: 무통장입금, 나이스/네이버/카카오페이 현금영수증 발행 총합

Sheet 2021.04~06
A1: 2021년 4 ~ 6월 매출금액 결제수단 별 정리
B2: 구분 | C2: 금액 | D2: 참고
A3: 홈페이지 (나이스페이 & 무통장입금) | B3: 카드결제 | C3: 434538451
B4: 무통장입금 | C4: 51963522 | D4: 무통장입금액-취소환불금액(53,351,726-1,388,204) / 일부 현금영수증 발행됨
B5: 계좌이체 | C5: 1066158 | D5: 실시간 계좌이체(이 중 일부 현금영수증 발행됨)
B6: 가상계좌 | C6: 2150682 | D6: 이 중 일부 요청건 현금영수증 발행됨
B7: 기타매출 | C7: 22125729 | D7: 핸드폰결제
B8: 합계 | C8: =SUM(C3:C7) -> 511844542
A9: 네이버페이 | B9: 카드결제 | C9: 110438453 | D9: 신용카드 매출
B10: 현금영수증(소득공제) | C10: 55765104
B11: 현금영수증(지출증빙) | C11: 3492084
B12: 기타 | C12: 11729720 | D12: 네이버포인트, 현금영수증 미발행 건 등
B13: 합계 | C13: =SUM(C9:C12) -> 181425361
A14: 홈페이지 (카카오페이) | B14: 카드결제 | C14: 58606880 | D14: 신용카드 매출
B15: 현금 | C15: 94229917 | D15: 카카오페이 사용 시 등록번호로 현금영수증 자동발행
B16: 합계 | C16: =SUM(C14:C15) -> 152836797
A17: 네이버 스마트스토어 | B17: 카드결제 | C17: 24989166
B18: 현금영수증(소득공제) | C18: 11034311
B19: 현금영수증(지출증빙) | C19: 1038950
B20: 기타 | C20: 3871333 | D20: 네이버포인트, 현금영수증 미발행 건 등
B21: 합계 | C21: =SUM(C17:C20) -> 40933760
A22: KOCES (오프라인카드결제) | B22: 카드결제 | C22: 701100
B23: 합계 | C23: =SUM(C22) -> 701100
A24: 매출 총합 | C24: =C8+C13+C16+C21+C23 -> 887741560
A25: 홈택스 현금영수증 | B25: 4월 | C25: 67389275
B26: 5월 | C26: 65805623
B27: 6월 | C27: 69952901
B28: 합계 | C28: =SUM(C25:C27) -> 203147799 | D28: 무통장입금, 나이스/네이버/카카오페이 현금영수증 발행 총합

Sheet 2021.07~09
B1: 2021년 7 ~9월 매출금액 결제수단 별 정리
C2: 구분 | D2: 금액 | E2: 참고
A3: 머드스콘 | B3: 무통장입금 | C3: 무통장입금 | D3: 52625509 | E3: 무통장입금액-취소환불금액(54,194,026-1,568,517) / 일부 현금영수증 발행됨
B4: 나이스페이 | C4: 카드결제 | D4: 438242613
C5: 계좌이체 | D5: 976912 | E5: 실시간 계좌이체(이 중 일부 현금영수증 발행됨)
C6: 가상계좌 | D6: 1524164 | E6: 이 중 일부 요청건 현금영수증 발행됨
C7: 기타매출 | D7: 22888409 | E7: 핸드폰결제
C8: 합계 | D8: =SUM(D4:D7) -> 463632098
B9: 네이버페이 | C9: 카드결제 | D9: 89310703 | E9: 신용카드 매출
C10: 현금영수증(소득공제) | D10: 47525823
C11: 현금영수증(지출증빙) | D11: 3067919
C12: 기타 | D12: 10074028 | E12: 네이버포인트, 현금영수증 미발행 건 등
C13: 합계 | D13: =SUM(D9:D12) -> 149978473
B14: 홈페이지 (카카오페이) | C14: 카드결제 | D14: 78644844 | E14: 신용카드 매출
C15: 현금 | D15: 120678800 | E15: 카카오페이 사용 시 등록번호로 현금영수증 자동발행
C16: 합계 | D16: =SUM(D14:D15) -> 199323644
B17: 네이버 스마트스토어 | C17: 카드결제 | D17: 20199598
C18: 현금영수증(소득공제) | D18: 9077176
C19: 현금영수증(지출증빙) | D19: 922120
C20: 기타 | D20: 2856246 | E20: 네이버포인트, 현금영수증 미발행 건 등
C21: 합계 | D21: =SUM(D17:D20) -> 33055140
B22: KOCES (오프라인카드결제) | C22: 카드결제 | D22: 0
C23: 합계 | D23: 0
A24: 머드상회 | B24: 토스페이먼츠 | C24: 카드결제 | D24: 18302840
C25: 현금영수증 | D25: 2620342
C26: 합계 | D26: =SUM(D24:D25) -> 20923182
B27: 페이코 | C27: 카드결제 | D27: 1300474
C28: 기타(포인트) | D28: 754916
C29: 합계 | D29: =SUM(D27:D28) -> 2055390
B30: 모빌리언스 (머드상회/면세품목) | C30: 핸드폰결제 | D30: 918490
B31: 무통장입금 | C31: 무통장입금 | D31: 3281015 | E31: 무통장입금액-취소환불금액(3,337,625 - 56,610) / 일부 현금영수증 발행됨
A32: 매출 총합 | D32: =SUM(D3,D8,D13,D16,D21,D23,D26,D29,D30,D31) -> 925792941
A33: 홈택스 현금영수증 | C33: 7월 | D33: 78814317
C34: 8월 | D34: 78607837
C35: 9월 | D35: 59523193
C36: 합계 | D36: =SUM(D33:D35) -> 216945347 | E36: 머드스콘 / 머드상회 현금영수증 발행 총합

Sheet 2021.10~12
B1: 2021년 10 ~ 12월 매출금액 결제수단 별 정리
C2: 구분 | D2: 금액 | E2: 참고
A3: 머드스콘 | B3: 무통장입금 | C3: 무통장입금 | D3: 52728488 | E3: 무통장입금액-취소환불금액(53,886,579-1,158,091) / 일부 현금영수증 발행됨
B4: 나이스페이 | C4: 카드결제 | D4: 79479066
C5: 계좌이체 | D5: 197980 | E5: 실시간 계좌이체(이 중 일부 현금영수증 발행됨)
C6: 가상계좌 | D6: 268816 | E6: 이 중 일부 요청건 현금영수증 발행됨
C7: 기타매출 | D7: 4786310 | E7: 핸드폰결제
C8: 합계 | D8: =SUM(D4:D7) -> 84732172
B9: 토스페이먼츠 | C9: 신용/체크카드 | D9: 328711076
C10: 현금영수증 발행분 합계 | D10: 27703045 | E10: 가상계좌, 계좌이체, 현금영수증 별도입금 등 현금영수증 발행건
C11: 기타 합계 | D11: 5423517 | E11: 가상계좌, 계좌이체, PAYCO포인트(정규 영수증 외 매출분)
C12: 합계 | D12: =SUM(D9:D11) -> 361837638
B13: 네이버페이 | C13: 카드결제 | D13: 72666489 | E13: 신용카드 매출
C14: 현금영수증(소득공제) | D14: 38947453
C15: 현금영수증(지출증빙) | D15: 3036523
C16: 기타 | D16: 9975296 | E16: 네이버포인트, 현금영수증 미발행 건 등
C17: 합계 | D17: =SUM(D13:D16) -> 124625761
B18: 카카오페이 | C18: 카드결제 | D18: 89438120 | E18: 신용카드 매출
C19: 현금 | D19: 118547138 | E19: 카카오페이 사용 시 등록번호로 현금영수증 자동발행
C20: 합계 | D20: =SUM(D18:D19) -> 207985258
B21: 네이버 스마트스토어 | C21: 카드결제 | D21: 18408124
C22: 현금영수증(소득공제) | D22: 9926883
C23: 현금영수증(지출증빙) | D23: 1251835
C24: 기타 | D24: 2656518 | E24: 네이버포인트, 현금영수증 미발행 건 등
C25: 합계 | D25: =SUM(D21:D24) -> 32243360
B26: KOCES (오프라인카드결제) | C26: 카드결제 | D26: 0
C27: 합계 | D27: 0
A28: 머드상회 (면세: 고구마, 사과) | B28: 토스페이먼츠 | C28: 카드결제 | D28: 15732568
C29: 현금영수증 | D29: 2347631 | E29: 현금영수증 발행분
C30: 기타 합계 | D30: 33300 | E30: 정규 영수증 외 매출분
C31: 합계 | D31: =SUM(D28:D30) -> 18113499
B32: 네이버페이 | C32: 카드결제 | D32: 6431487
C33: 현금영수증(소득공제) | D33: 2386327
C34: 현금영수증(지출증빙) | D34: 195682
C35: 기타 | D35: 671216
C36: 합계 | D36: =SUM(D32:D35) -> 9684712
B37: 페이코 | C37: 카드결제 | D37: 730634
C38: 기타(포인트) | D38: 504879
C39: 합계 | D39: =SUM(D37:D38) -> 1235513
B40: 모빌리언스 (머드상회/면세품목) | C40: 핸드폰결제 | D40: 1031755
...
